2025-10-05 17:19:16,599 INFO    MainThread:2416410 [wandb_setup.py:_flush():81] Current SDK version is 0.22.1
2025-10-05 17:19:16,599 INFO    MainThread:2416410 [wandb_setup.py:_flush():81] Configure stats pid to 2416410
2025-10-05 17:19:16,599 INFO    MainThread:2416410 [wandb_setup.py:_flush():81] Loading settings from /home/sidcs/.config/wandb/settings
2025-10-05 17:19:16,599 INFO    MainThread:2416410 [wandb_setup.py:_flush():81] Loading settings from /gpfs/accounts/profdj_root/profdj0/sidcs/codebase/speaker_embedding_codebase/wandb/settings
2025-10-05 17:19:16,599 INFO    MainThread:2416410 [wandb_setup.py:_flush():81] Loading settings from environment variables
2025-10-05 17:19:16,599 INFO    MainThread:2416410 [wandb_init.py:setup_run_log_directory():705] Logging user logs to ./wandb_logs/wandb/run-20251005_171916-q3luikw1/logs/debug.log
2025-10-05 17:19:16,600 INFO    MainThread:2416410 [wandb_init.py:setup_run_log_directory():706] Logging internal logs to ./wandb_logs/wandb/run-20251005_171916-q3luikw1/logs/debug-internal.log
2025-10-05 17:19:16,600 INFO    MainThread:2416410 [wandb_init.py:init():832] calling init triggers
2025-10-05 17:19:16,600 INFO    MainThread:2416410 [wandb_init.py:init():837] wandb.init called with sweep_config: {}
config: {'_wandb': {}}
2025-10-05 17:19:16,600 INFO    MainThread:2416410 [wandb_init.py:init():880] starting backend
2025-10-05 17:19:18,073 INFO    MainThread:2416410 [wandb_init.py:init():883] sending inform_init request
2025-10-05 17:19:18,101 INFO    MainThread:2416410 [wandb_init.py:init():891] backend started and connected
2025-10-05 17:19:18,103 INFO    MainThread:2416410 [wandb_init.py:init():961] updated telemetry
2025-10-05 17:19:18,115 INFO    MainThread:2416410 [wandb_init.py:init():985] communicating run to backend with 90.0 second timeout
2025-10-05 17:19:18,670 INFO    MainThread:2416410 [wandb_init.py:init():1036] starting run threads in backend
2025-10-05 17:19:19,691 INFO    MainThread:2416410 [wandb_run.py:_console_start():2506] atexit reg
2025-10-05 17:19:19,691 INFO    MainThread:2416410 [wandb_run.py:_redirect():2354] redirect: wrap_raw
2025-10-05 17:19:19,691 INFO    MainThread:2416410 [wandb_run.py:_redirect():2423] Wrapping output streams.
2025-10-05 17:19:19,691 INFO    MainThread:2416410 [wandb_run.py:_redirect():2446] Redirects installed.
2025-10-05 17:19:19,719 INFO    MainThread:2416410 [wandb_init.py:init():1076] run started, returning control to user process
2025-10-05 17:19:19,746 INFO    MainThread:2416410 [wandb_run.py:_config_callback():1392] config_cb None None {'num_class': 5796}
2025-10-05 17:19:49,684 INFO    wandb-AsyncioManager-main:2416410 [service_client.py:_forward_responses():80] Reached EOF.
2025-10-05 17:19:49,684 INFO    wandb-AsyncioManager-main:2416410 [mailbox.py:close():137] Closing mailbox, abandoning 1 handles.
2025-10-05 17:19:50,059 ERROR   MainThread:2416410 [redirect.py:_on_write():664] [all runs] error in stderr callback
Traceback (most recent call last):
  File "/scratch/profdj_root/profdj0/sidcs/envs/miniconda3/envs/mtse/lib/python3.10/site-packages/wandb/sdk/lib/redirect.py", line 662, in _on_write
    cb(written_data)
  File "/scratch/profdj_root/profdj0/sidcs/envs/miniconda3/envs/mtse/lib/python3.10/site-packages/wandb/sdk/wandb_run.py", line 2433, in <lambda>
    lambda data: self._console_raw_callback("stderr", data),
  File "/scratch/profdj_root/profdj0/sidcs/envs/miniconda3/envs/mtse/lib/python3.10/site-packages/wandb/sdk/wandb_run.py", line 399, in wrapper
    return func(self, *args, **kwargs)
  File "/scratch/profdj_root/profdj0/sidcs/envs/miniconda3/envs/mtse/lib/python3.10/site-packages/wandb/sdk/wandb_run.py", line 457, in wrapper_fn
    return func(self, *args, **kwargs)
  File "/scratch/profdj_root/profdj0/sidcs/envs/miniconda3/envs/mtse/lib/python3.10/site-packages/wandb/sdk/wandb_run.py", line 1595, in _console_raw_callback
    self._backend.interface.publish_output_raw(name, data)
  File "/scratch/profdj_root/profdj0/sidcs/envs/miniconda3/envs/mtse/lib/python3.10/site-packages/wandb/sdk/interface/interface.py", line 802, in publish_output_raw
    self._publish_output_raw(o)
  File "/scratch/profdj_root/profdj0/sidcs/envs/miniconda3/envs/mtse/lib/python3.10/site-packages/wandb/sdk/interface/interface_shared.py", line 37, in _publish_output_raw
    self._publish(rec)
  File "/scratch/profdj_root/profdj0/sidcs/envs/miniconda3/envs/mtse/lib/python3.10/site-packages/wandb/sdk/interface/interface_sock.py", line 43, in _publish
    self._asyncer.run(lambda: self._client.publish(request))
  File "/scratch/profdj_root/profdj0/sidcs/envs/miniconda3/envs/mtse/lib/python3.10/site-packages/wandb/sdk/lib/asyncio_manager.py", line 136, in run
    return future.result()
  File "/scratch/profdj_root/profdj0/sidcs/envs/miniconda3/envs/mtse/lib/python3.10/concurrent/futures/_base.py", line 458, in result
    return self.__get_result()
  File "/scratch/profdj_root/profdj0/sidcs/envs/miniconda3/envs/mtse/lib/python3.10/concurrent/futures/_base.py", line 403, in __get_result
    raise self._exception
  File "/scratch/profdj_root/profdj0/sidcs/envs/miniconda3/envs/mtse/lib/python3.10/site-packages/wandb/sdk/lib/asyncio_manager.py", line 219, in _wrap
    return await fn()
  File "/scratch/profdj_root/profdj0/sidcs/envs/miniconda3/envs/mtse/lib/python3.10/site-packages/wandb/sdk/lib/service/service_client.py", line 38, in publish
    await self._send_server_request(request)
  File "/scratch/profdj_root/profdj0/sidcs/envs/miniconda3/envs/mtse/lib/python3.10/site-packages/wandb/sdk/lib/service/service_client.py", line 64, in _send_server_request
    await self._writer.drain()
  File "/scratch/profdj_root/profdj0/sidcs/envs/miniconda3/envs/mtse/lib/python3.10/asyncio/streams.py", line 371, in drain
    await self._protocol._drain_helper()
  File "/scratch/profdj_root/profdj0/sidcs/envs/miniconda3/envs/mtse/lib/python3.10/asyncio/streams.py", line 167, in _drain_helper
    raise ConnectionResetError('Connection lost')
ConnectionResetError: Connection lost
2025-10-05 17:19:50,157 ERROR   MainThread:2416410 [redirect.py:_on_write():664] [all runs] error in stderr callback
Traceback (most recent call last):
  File "/scratch/profdj_root/profdj0/sidcs/envs/miniconda3/envs/mtse/lib/python3.10/site-packages/wandb/sdk/lib/redirect.py", line 662, in _on_write
    cb(written_data)
  File "/scratch/profdj_root/profdj0/sidcs/envs/miniconda3/envs/mtse/lib/python3.10/site-packages/wandb/sdk/wandb_run.py", line 2433, in <lambda>
    lambda data: self._console_raw_callback("stderr", data),
  File "/scratch/profdj_root/profdj0/sidcs/envs/miniconda3/envs/mtse/lib/python3.10/site-packages/wandb/sdk/wandb_run.py", line 399, in wrapper
    return func(self, *args, **kwargs)
  File "/scratch/profdj_root/profdj0/sidcs/envs/miniconda3/envs/mtse/lib/python3.10/site-packages/wandb/sdk/wandb_run.py", line 457, in wrapper_fn
    return func(self, *args, **kwargs)
  File "/scratch/profdj_root/profdj0/sidcs/envs/miniconda3/envs/mtse/lib/python3.10/site-packages/wandb/sdk/wandb_run.py", line 1595, in _console_raw_callback
    self._backend.interface.publish_output_raw(name, data)
  File "/scratch/profdj_root/profdj0/sidcs/envs/miniconda3/envs/mtse/lib/python3.10/site-packages/wandb/sdk/interface/interface.py", line 802, in publish_output_raw
    self._publish_output_raw(o)
  File "/scratch/profdj_root/profdj0/sidcs/envs/miniconda3/envs/mtse/lib/python3.10/site-packages/wandb/sdk/interface/interface_shared.py", line 37, in _publish_output_raw
    self._publish(rec)
  File "/scratch/profdj_root/profdj0/sidcs/envs/miniconda3/envs/mtse/lib/python3.10/site-packages/wandb/sdk/interface/interface_sock.py", line 43, in _publish
    self._asyncer.run(lambda: self._client.publish(request))
  File "/scratch/profdj_root/profdj0/sidcs/envs/miniconda3/envs/mtse/lib/python3.10/site-packages/wandb/sdk/lib/asyncio_manager.py", line 136, in run
    return future.result()
  File "/scratch/profdj_root/profdj0/sidcs/envs/miniconda3/envs/mtse/lib/python3.10/concurrent/futures/_base.py", line 458, in result
    return self.__get_result()
  File "/scratch/profdj_root/profdj0/sidcs/envs/miniconda3/envs/mtse/lib/python3.10/concurrent/futures/_base.py", line 403, in __get_result
    raise self._exception
  File "/scratch/profdj_root/profdj0/sidcs/envs/miniconda3/envs/mtse/lib/python3.10/site-packages/wandb/sdk/lib/asyncio_manager.py", line 219, in _wrap
    return await fn()
  File "/scratch/profdj_root/profdj0/sidcs/envs/miniconda3/envs/mtse/lib/python3.10/site-packages/wandb/sdk/lib/service/service_client.py", line 38, in publish
    await self._send_server_request(request)
  File "/scratch/profdj_root/profdj0/sidcs/envs/miniconda3/envs/mtse/lib/python3.10/site-packages/wandb/sdk/lib/service/service_client.py", line 64, in _send_server_request
    await self._writer.drain()
  File "/scratch/profdj_root/profdj0/sidcs/envs/miniconda3/envs/mtse/lib/python3.10/asyncio/streams.py", line 371, in drain
    await self._protocol._drain_helper()
  File "/scratch/profdj_root/profdj0/sidcs/envs/miniconda3/envs/mtse/lib/python3.10/asyncio/streams.py", line 167, in _drain_helper
    raise ConnectionResetError('Connection lost')
ConnectionResetError: Connection lost
